Workbook

Sheet 1. Plan de Pruebas
A1: Plan de Pruebas
A2: Plan de pruebas funcional ajustado para evaluación técnica y control del proyecto.
A4: Información del Documento
A5: Plan de Pruebas Funcional - Aplicación Móvil La Piña Brava | D5: TP-2026-LPB01
A7: Organización Emisora: | D7: Responsable:
A8: Equipo de Aseguramiento de Calidad (QA) | D8: Yessica Sánchez Beristain
A9: Contexto de las Pruebas
A10: Proyecto/Subproceso de Prueba:
A11: Este plan de pruebas contempla la evaluación funcional de la nueva aplicación móvil de La Piña Brava. El análisis abarca la validación de la Historia de Usuario de Registro de usuarios, la exploración del catálogo de productos y la ejecución de flujos de navegación sobre la maqueta de Figma (búsqueda y carrito de compras).
A14: Elementos a Probar:
A15: Los elementos a probar incluyen: • Creación de cuenta • Inicio de sesión • Cátalogo de productos y busqueda • Carrito de compras
A20: Alcance de las Pruebas:
A21: El alcance comprende la ejecución de pruebas funcionales manuales, validación de reglas de negocio en formularios y detección de defectos en la interfaz sobre la maqueta interactiva. No se consideran en esta etapa pruebas automatizadas, pruebas de rendimiento ni estresamiento de la aplicación.

Sheet 2. Particiones Equivalentes
A1: PARTICIONES EQUIVALENTES Y ANÁLISIS DE VALORES LÍMITE
A4: Campo / Entidad | B4: Clase de Entrada | C4: Rango / Condición Evaluada | D4: Tipo de Partición | E4: Valor de Prueba (Ejemplo) | F4: Resultado Esperado
A5: Nombre(s) | B5: Longitud Válida | C5: Entre 1 y 20 caracteres alfanuméricos | D5: Válida | E5: Juan Carlos | F5: Acepta valor y permite continuar
A6: Nombre(s) | B6: Longitud Excesiva | C6: Más de 20 caracteres alfanuméricos | D6: Inválida | E6: Juan Carlos Perez Gomez De La Rosa | F6: Muestra mensaje de error: máximo 20 caracteres
A7: Nombre(s) | B7: Campo Vacío | C7: Omitir el campo obligatorio | D7: Inválida | E7: [Vacío] | F7: Muestra en rojo 'Campo requerido'
A8: Correo electrónico | B8: Formato Válido | C8: Estructura correcta XXX@XXX.XXX | D8: Válida | E8: carlos@test.com | F8: Acepta el correo y permite continuar
A9: Correo electrónico | B9: Formato Inválido | C9: Estructura sin @ ni dominio | D9: Inválida | E9: usuariodominio.com | F9: Muestra alerta de estructura de correo inválida
A10: Correo electrónico | B10: Campo Vacío | C10: Omitir el campo obligatorio | D10: Inválida | E10: [Vacío] | F10: Muestra en rojo 'Campo requerido'
A11: Contraseña | B11: Longitud y Reglas Válidas | C11: 6 a 12 char, 1 mayúscula, 1 número, sin símbolos | D11: Válida | E11: Pina2026 | F11: Acepta la contraseña correctamente
A12: Contraseña | B12: Longitud Menor a 6 | C12: Menos de 6 caracteres (ej. 5) | D12: Inválida | E12: Pina2 | F12: Error: longitud mínima de 6 caracteres
A13: Contraseña | B13: Longitud Mayor a 12 | C13: Más de 12 caracteres (ej. 13) | D13: Inválida | E13: Pinabrava2026! | F13: Error: longitud máxima de 12 caracteres
A14: Contraseña | B14: Sin Mayúscula | C14: Texto en minúsculas con números | D14: Inválida | E14: pina2026 | F14: Error: debe contener al menos una mayúscula
A15: Contraseña | B15: Sin Número | C15: Texto con mayúsculas sin números | D15: Inválida | E15: Pinabrava | F15: Error: debe contener al menos un número
A16: Contraseña | B16: Caracteres Especiales | C16: Incluye símbolos (!, #, $, %) | D16: Inválida | E16: Pina2026! | F16: Error: solo acepta caracteres alfanuméricos
A17: Teléfono | B17: 10 Dígitos Numéricos | C17: Exactamente 10 números (opcional) | D17: Válida | E17: 5512345678 | F17: Acepta el teléfono correctamente
A18: Teléfono | B18: Campo Vacío | C18: Omitir el campo opcional | D18: Válida | E18: [Vacío] | F18: Permite el registro sin marcar error
A19: Barra de Búsqueda | B19: Palabra Existente | C19: Término presente en catálogo | D19: Válida | E19: Mango | F19: Muestra lista de productos coincidentes
A20: Barra de Búsqueda | B20: Sin Coincidencias | C20: Término inexistente en catálogo | D20: Inválida | E20: Jabón | F20: Muestra pantalla 'No se han encontrado productos'

Sheet 3. Tabla de Decisión
A1: TABLA DE DECISIÓN
A4: Condiciones / Reglas de Negocio | B4: Regla 1 (Éxito) | C4: Regla 2 (Vacíos) | D4: Regla 3 (Pass Inválida) | E4: Regla 4 (Term. No Acept.) | F4: Regla 5 (Correo Dup.)
A5: ¿Campos obligatorios (Nombre, Correo, Contraseña) completos? | B5: SI | C5: NO | D5: SI | E5: SI | F5: SI
A6: ¿Contraseña cumple complejidad (6-12 char, 1 mayús, 1 num)? | B6: SI | C6: SI | D6: NO | E6: SI | F6: SI
A7: ¿Casilla de Términos y Condiciones marcada? | B7: SI | C7: SI | D7: SI | E7: NO | F7: SI
A8: ¿Correo electrónico NO registrado previamente en BD? | B8: SI | C8: SI | D8: SI | E8: SI | F8: NO
A9: ACCIONES / RESULTADOS ESPERADOS (ENTONCES...)
A10: Desplegar Pop-up '¡Bienvenido a la App de La Piña Brava!' | B10: SI | C10: NO | D10: NO | E10: NO | F10: NO
A11: Mostrar alerta 'Campo requerido' en texto rojo | B11: NO | C11: SI | D11: NO | E11: SI | F11: NO
A12: Mostrar mensaje de error de formato de contraseña | B12: NO | C12: NO | D12: SI | E12: NO | F12: NO
A13: Mostrar mensaje 'El correo ya se encuentra registrado' | B13: NO | C13: NO | D13: NO | E13: NO | F13: SI

Sheet RF Casos Prueba
A1: Caso de Prueba (CP)
A2: Objetivo: Validar flujos de
A4: Definido por: Yessica Sánchez Beristain | D4: Fecha de definición: 11/09/2026 | E4: Fase: Análisis, diseño y desarrollo
A5: Inter Dependencias CP: N/A | G5: Plataforma(s):
A6: Preparación de Prueba (Prerequisitos): Ambiente en PRO
A7: Fecha de Ejecución: 11/09/2026 | C7: Ejecutado por: Yessica Sánchez Beristain | E7: Fecha de Validación: 11/09/2026 | G7: Validado por: Yessica Sánchez Beristain
A9: RF / Módulo | B9: Nombre del Requerimiento | C9: Descripción / Escenario Evaluado | D9: Total CP | E9: CP Exitosos | F9: CP Fallidos | G9: Estatus RF
A10: RF1 | B10: Crear Cuenta / Registro | C10: Validación de formulario de registro, campos obligatorios, reglas de contraseña (6-12 char, 1 mayús, 1 num), confirmación de contraseña, términos y condiciones y pop-up de bienvenida. | D10: =COUNTIF('4. Matriz Casos de Prueba'!B:B, $A10) -> 15 | E10: =COUNTIFS('4. Matriz Casos de Prueba'!B:B, $A10, '4. Matriz Casos de Prueba'!G:G, "Exitoso") -> 3 | F10: =COUNTIFS('4. Matriz Casos de Prueba'!B:B, $A10, '4. Matriz Casos de Prueba'!G:G, "Falló") -> 7 | G10: Falló
A11: RF2 | B11: Búsqueda de Productos | C11: Validación de barra de búsqueda por texto libre, búsquedas recientes y manejo de productos no encontrados. | D11: =COUNTIF('4. Matriz Casos de Prueba'!B:B, $A11) -> 1 | E11: =COUNTIFS('4. Matriz Casos de Prueba'!B:B, $A11, '4. Matriz Casos de Prueba'!G:G, "Exitoso") -> 0 | F11: =COUNTIFS('4. Matriz Casos de Prueba'!B:B, $A11, '4. Matriz Casos de Prueba'!G:G, "Falló") -> 1 | G11: Falló
A12: RF3 | B12: Menú Lateral Hamburguesa | C12: Validación de despliegue y cierre de menú lateral con opciones de perfil, direcciones y pagos. | D12: =COUNTIF('4. Matriz Casos de Prueba'!B:B, $A12) -> 2 | E12: =COUNTIFS('4. Matriz Casos de Prueba'!B:B, $A12, '4. Matriz Casos de Prueba'!G:G, "Exitoso") -> 0 | F12: =COUNTIFS('4. Matriz Casos de Prueba'!B:B, $A12, '4. Matriz Casos de Prueba'!G:G, "Falló") -> 2 | G12: Falló
A13: RF4 | B13: Picantómetro | C13: Validación de filtro categórico por nivel de picante (Los peligrosos, Los bravos, Los normalillos, Los levecitos). | D13: =COUNTIF('4. Matriz Casos de Prueba'!B:B, $A13) -> 4 | E13: =COUNTIFS('4. Matriz Casos de Prueba'!B:B, $A13, '4. Matriz Casos de Prueba'!G:G, "Exitoso") -> 0 | F13: =COUNTIFS('4. Matriz Casos de Prueba'!B:B, $A13, '4. Matriz Casos de Prueba'!G:G, "Falló") -> 4 | G13: Falló
A14: RF5 | B14: Categorías de Productos | C14: Validación de la cuadrícula de categorías (Aciditos, Frutal, Gomitas, Botana, Salsa, Confitado) y vista de productos. | D14: =COUNTIF('4. Matriz Casos de Prueba'!B:B, $A14) -> 8 | E14: =COUNTIFS('4. Matriz Casos de Prueba'!B:B, $A14, '4. Matriz Casos de Prueba'!G:G, "Exitoso") -> 3 | F14: =COUNTIFS('4. Matriz Casos de Prueba'!B:B, $A14, '4. Matriz Casos de Prueba'!G:G, "Falló") -> 5 | G14: Falló
A15: RF6 | B15: Detalle de Producto y Favoritos | C15: Validación de modal emergente de detalle de producto, congruencia de descripción/título e icono de corazón/favoritos. | D15: =COUNTIF('4. Matriz Casos de Prueba'!B:B, $A15) -> 5 | E15: =COUNTIFS('4. Matriz Casos de Prueba'!B:B, $A15, '4. Matriz Casos de Prueba'!G:G, "Exitoso") -> 2 | F15: =COUNTIFS('4. Matriz Casos de Prueba'!B:B, $A15, '4. Matriz Casos de Prueba'!G:G, "Falló") -> 3 | G15: Falló
A16: RF7 | B16: Carrito de Compras | C16: Validación de desglose de precios, descuento 3x2, incremento de cantidad (+/-), productos sugeridos y redirección a login. | D16: =COUNTIF('4. Matriz Casos de Prueba'!B:B, $A16) -> 8 | E16: =COUNTIFS('4. Matriz Casos de Prueba'!B:B, $A16, '4. Matriz Casos de Prueba'!G:G, "Exitoso") -> 3 | F16: =COUNTIFS('4. Matriz Casos de Prueba'!B:B, $A16, '4. Matriz Casos de Prueba'!G:G, "Falló") -> 5 | G16: Falló
A17: RF8 | B17: Dirección y Método de Pago | C17: Validación de selección de direcciones guardadas, tarjetas registradas, alta de nuevas direcciones/tarjetas y flujo de checkout. | D17: =COUNTIF('4. Matriz Casos de Prueba'!B:B, $A17) -> 9 | E17: =COUNTIFS('4. Matriz Casos de Prueba'!B:B, $A17, '4. Matriz Casos de Prueba'!G:G, "Exitoso") -> 0 | F17: =COUNTIFS('4. Matriz Casos de Prueba'!B:B, $A17, '4. Matriz Casos de Prueba'!G:G, "Falló") -> 9 | G17: Falló

Sheet 4. Matriz Casos de Prueba
A1: ID | B1: RF | C1: DADO | D1: CUANDO | E1: ENTONCES | F1: RESPONSABLE | G1: Estatus | H1: OBSERVACIONES
A2: R1 | B2: Crear cuenta
A3: LPB-CP001 | B3: RF1 | C3: Creación de cuenta | D3: Ingresar nombre, correo electronico, contraseña, telefono (opcional), aceptar terminos y condiciones. Dar click en "Registarme" | E3: Recibir un pop-up con mensaje: "registro exitoso", ¡Bienvenido a la App de La Piña Brava!” y un botón de continuar. | F3: Yessica | G3: Falló
A4: LPB-CP002 | B4: RF1 | C4: Creación de cuenta | D4: Ingresar nombre, correo electronico, contraseña, telefono (opcional), aceptar terminos y condiciones. Dar click en "Registarme" | E4: Recibir un pop-up con mensaje: "registro exitoso", ¡Bienvenido a la App de La Piña Brava!” y un botón de continuar. Al presionar el botón Continuar se mostrar la pantalla inicial de la aplicación. | F4: Yessica | G4: Exitoso | H4: No se muestra ningun pop-up, tampoco el botón de continuar para hacer el proceso de login
A5: LPB-CP003 | B5: RF1 | C5: Creación de cuenta | D5: Ingresar nombre, correo electronico, contraseña, aceptar terminos y condiciones. Dar click en "Registarme" | E5: Recibir un modal que la cuenta se ha creado, se redirige hacaia la pantalla de login | F5: Yessica | G5: Exitoso
A6: LPB-CP004 | B6: RF1 | C6: Campo nombre 20 caracteres | D6: Ingresa en el campo Nombre un texto de 20 caracteres alfanuméricos | E6: El sistema permite el ingreso del texto correctamente sin marcar error | F6: Yessica
A7: LPB-CP005 | B7: RF1 | C7: Campo nombre 20 caracteres | D7: Ingresa en el campo Nombre un texto de más 20 caracteres alfanuméricos | E7: Validar que el sistema nos muestre un mensaje de que el campo solo acepte 20 caracteres | F7: Yessica
A8: LPB-CP006 | B8: RF1 | C8: Campos vacios | D8: Dejar todos los campos vacios y aceptar terminos y condiciones. Dar click en "Registrarme" | E8: Validar que el sistema no permita el registro, en los campos obligatorios debe visualizarse en color rojo "campo requerido" | F8: Yessica | G8: Exitoso
A9: LPB-CP007 | B9: RF1 | C9: Campo correo electronico | D9: Ingresa en el campo Correo un texto sin formato válido (usuarioregistro.com) y da clic en "Registrarme" | E9: Validar que el sistema muestre mensaje de alerta indicando la estructura correcta el correo electronico | F9: Yessica
A10: LPB-CP008 | B10: RF1 | C10: Contraseña de 6 - 12 caracteres | D10: Ingresar campos de Nombre, correo y en el campos de contraseña ingresar 8 caracteres con al menos una mayúscula y un número (Pina2026) y da clic en "Registrarme" | E10: Validar que el sistema acepte la contraseña por cumplir con la longitud de 6 a 12 caracteres alfanuméricos | F10: Yessica
A11: LPB-CP009 | B11: RF1 | C11: Contraseña de menos de 6 caracteres | D11: Ingresar campos de Nombre, correo y en el campos de contraseña ingresar 5 caracteres con al menos una mayúscula y un número ( Pina2) y da clic en "Registrarme" | E11: Validar que el sistema no acepte la contraseña por cumplir con la longitud de 6 a 12 caracteres alfanuméricos y nos muestre un mensaje de el minimo de caracteres aceptados. | F11: Yessica
A12: LPB-CP010 | B12: RF1 | C12: Confirmar contraseña | D12: Repetir nuevamente contraseña en el campos de "Confirmar contraseña" | E12: Validar que al ser contraseñas totalmente iguales el sistemas nos deje registrarnos correctamente | F12: Yessica | G12: Falló | H12: No hay campo de confimar contraseña
A13: LPB-CP011 | B13: RF1 | C13: Confirmar contraseña | D13: Repetir nuevamente contraseña en el campos de "Confirmar contraseña" pero ingresando la contraseña incorectamnete | E13: Validar que el sistema nos mande un mensaje que las contraseñas no coinciden | F13: Yessica | G13: Falló | H13: No hay campo de confimar contraseña
A14: LPB-CP012 | B14: RF1 | C14: Visualizar terminos y condiciones | D14: Da clic sobre el enlace/hipervínculo de "Términos y Condiciones | E14: Validar que el sistema abra la pantalla o modal que despliega los avisos legales indicados por La Piña Brava | F14: Yessica | G14: Falló | H14: No podemos dar click
A15: LPB-CP013 | B15: RF1 | C15: Aceptar terminos y condiciones | D15: Seleccionar la casilla tipo check de Aceptar términos y condiciones y dar clic en Registrarme | E15: Validar que la casilla se muestre seleccionada con un punto dentro de ella y que el sistema permita completar el registro exitosamente | F15: Yessica | G15: Falló | H15: No se muestra un punto dentro del check
A16: LPB-CP014 | B16: RF1 | C16: Check de terminos y condiciones | D16: Ingresar nombre, correo electronico, contraseña, telefono, no aceptar terminos y condiciones. Dar click en "Registarme" | E16: Validar que el sistema no permita el registro de la nueva, mostrar mensaje en color rojo "campo requerido" | F16: Yessica | G16: Falló | H16: No podemos ver las validaciones
A17: LPB-CP014 | B17: RF1 | C17: Olvido contraseña | D17: dar click en "Olvido contraseña" para poder restaurarla | E17: Validar que el sistema nos pida un correo electronico, para que se nos envie un enlace para una nueva contraseña | F17: Yessica | G17: Falló | H17: No cuenta con la funcionalidad
B18: Busquedas
A19: LPB-CP015 | B19: RF2 | C19: Usuarios se encuentra en ofertas del día | D19: Ingresa la palabra "Paletas" | E19: Validar que al realizar la búsqueda solo se obtengan resultados de "paletas" | F19: Yessica | G19: Falló | H19: Trae otros productos no relacionados
A20: LPB-CP016 | C20: el usuario visualiza las etiquetas en "Recientes". | D20: Hace clic sobre la etiqueta tamarindo | E20: Validar que se ejecute la búsqueda y muestre los productos asociados a "tamarindo". | F20: Yessica | G20: Falló | H20: No podemos realizar una búsqueda reciente
A21: RF3 | B21: Menú
A22: LPB-CP017 | B22: RF3 | C22: el usuario se encuentra en cualquier pantalla con el header superior. | D22: Hacer click en el icono de menú hamburguesa en la esquina superior izquierda | E22: El sistema despliega el menú lateral mostrando las opciones de navegación (Perfil, Mis Pedidos, Direcciones, Tarjetas, Ayuda, Cerrar Sesión). | F22: Yessica | G22: Falló | H22: Trae otros productos no relacionados
A23: LPB-CP018 | B23: RF3 | C23: el usuario tiene el menú lateral desplegado | D23: Hace clic fuera del menú | E23: El sistema oculta el menú lateral y regresa a la pantalla en la que se encontraba el usuario. | F23: Yessica | G23: Falló | H23: No realiza ninguna acción
A24: RF4 | B24: Picantómetro
A25: LPB-CP019 | B25: RF4 | C25: el usuario se encuentra en la sección "Elige con el picantómetro | D25: Hace clic sobre la opción "Los peligrosos | E25: El sistema filtra el catálogo mostrando únicamente los productos con el nivel de picante más alto | F25: Yessica | G25: Falló
A26: LPB-CP020 | B26: RF4 | C26: el usuario se encuentra en la sección "Elige con el picantómetro | D26: Hace clic sobre la opción "Los bravos" | E26: El sistema filtra el catálogo desplegando los productos con nivel de picante alto/intenso. | F26: Yessica | G26: Falló
A27: LPB-CP021 | B27: RF4 | C27: el usuario se encuentra en la sección "Elige con el picantómetro | D27: Hace clic sobre la opción "Los normalillos | E27: El sistema filtra la lista mostrando los productos con picante medio o moderado. | F27: Yessica | G27: Falló
A28: LPB-CP022 | B28: RF4 | C28: el usuario se encuentra en la sección "Elige con el picantómetro | D28: Hace clic sobre la opción "Los levecitos" | E28: El sistema muestra la lista de productos con sabor suave o picante muy bajo. | F28: Yessica | G28: Falló
A29: RF5 | B29: Categorias
A30: LPB-CP023 | B30: RF5 | C30: el usuario está en la pantalla principal de "Búsquedas" | D30: Visualiza r a cuadrícula de "Categorías" (Acidito, Frutal, Gomitas, Botana, Salsa, Confitado). | E30: Validar que las categorías muestran su imagen correspoendiente a su titulo | F30: Yessica | G30: Exitoso
A31: LPB-CP024 | B31: RF5 | C31: Selecciona la categoría "Aciditos" | D31: filtra el catálogo mostrando los productos correspondientes a la categoría "Aciditos" | E31: Validar productos relacioandos a la categoria | F31: Yessica | G31: Exitoso
A32: LPB-CP025 | B32: RF5 | C32: Selecciona la categoría "Frutal" | D32: filtra el catálogo mostrando los productos correspondientes a la categoría "Frutal" | E32: Validar productos relacioandos a la categoria | F32: Yessica | G32: Exitoso
A33: LPB-CP026 | B33: RF5 | C33: Selecciona la categoría "Gomitas" | D33: filtra el catálogo mostrando los productos correspondientes a la categoría "Gomitas" | E33: Validar productos relacioandos a la categoria | F33: Yessica | G33: Falló | H33: No podemos ingresar a la categoria
A34: LPB-CP027 | B34: RF5 | C34: Selecciona la categoría "Botana" | D34: filtra el catálogo mostrando los productos correspondientes a la categoría "Botana" | E34: Validar productos relacioandos a la categoria | F34: Yessica | G34: Falló | H34: No podemos ingresar a la categoria
A35: LPB-CP028 | B35: RF5 | C35: Selecciona la categoría "Salsa" | D35: filtra el catálogo mostrando los productos correspondientes a la categoría "Salsa" | E35: Validar productos relacioandos a la categoria | F35: Yessica | G35: Falló | H35: No podemos ingresar a la categoria
A36: LPB-CP029 | B36: RF5 | C36: Selecciona la categoría "Confitado" | D36: filtra el catálogo mostrando los productos correspondientes a la categoría "Confitado" | E36: Validar productos relacioandos a la categoria | F36: Yessica | G36: Falló | H36: No podemos ingresar a la categoria
A37: LPB-CP030 | B37: RF5 | C37: Seleción de categoria sin productos | D37: Selecionar una categoria sin productos | E37: Validar que muestre mensaje de "No se han encotrado productos" | F37: Yessica | G37: Falló | H37: No podemos ingresar a la categoria
A38: RF6 | B38: Detalle de producto
A39: LPB-CP031 | B39: RF6 | C39: usuario se encuentra en el catálogo "Ofertas del día". | D39: Dar click sobre la tarjeta del producto "Mango" | E39: Validar que el sistema despliega una ventana emergente/modal con el detalle del producto | F39: Yessica | G39: Exitoso
A40: LPB-CP032 | B40: RF6 | C40: visualizar el modal de detalle del producto | D40: Revisa el texto descriptivo del producto en el modal. | E40: El texto descriptivo debe ser congruente con el título del producto. | F40: Yessica | G40: Falló | H40: No coincide el titulo con la descripción del producto
...

Sheet 5. Incidencias y Bugs
A1: ID Incidente | B1: RF | C1: DESCRIPCIÓN DEL INCIDENTE | D1: CRITICIDAD | E1: REPORTA | F1: FECHA DE REPORTE | G1: FECHA DE ENTREGA | H1: ESTATUS | I1: EVIDENCIA | J1: COMENTARIOS
A2: DEF-1 | B2: RF1 | C2: No se encuentra el campo "Confirmar contraseña" | D2: Critica | E2: Yessica | F2: 45672 | H2: Pendiente | I2: Imagen
A3: DEF-2 | B3: RF6 | C3: El texto descriptivo del titulo no coincide con la descripción | D3: Media | E3: Yessica | F3: 45672 | H3: Pendiente | I3: Imagen
A4: DEF-3 | B4: RF7 | C4: Los botones de incremento, no añade las cantidades correctamente, aumenta solo de 1 y 3 | D4: Media | E4: Yessica | F4: 45672 | H4: Pendiente | I4: Video
A5: DEF-4 | B5: RF7 | C5: Cuando nos encontramos realizando una compra, y queremos iniciar sesión para completar la compra, damos click en "iniciar sesión" y no nos dirige al Login | D5: Critica | E5: Yessica | F5: 45672 | H5: Pendiente | I5: Video
A6: DEF-5 | B6: RF7 | C6: No se pueden agregar más productos al carrito | D6: Alta | E6: Yessica | F6: 45672 | H6: Pendiente | I6: Imagen
A7: DEF-6 | B7: RF7 | C7: Los productos sugeridos no se pueden agregar al carrito | D7: Alta | E7: Yessica | F7: 45672 | H7: Pendiente | I7: Imagen
A8: DEF-7 | B8: RF8 | C8: Duplicidad de direcciones de la casa y oficina en el modulos de direcciones | D8: Media | E8: Yessica | F8: 45672 | H8: Pendiente | I8: Imagen
A9: DEF-8 | B9: RF8 | C9: La primera y la tercera tarjeta muestran la misma terminación repetida. No se deberian añadir tarjetas duplicadass | D9: Media | E9: Yessica | F9: 45672 | H9: Pendiente | I9: Imagen
A10: DEF-9 | B10: RF8 | C10: Al tener productos en el carrito de compras y proceder con la compra, (dar click en realiazar compra") la app se rompe | D10: Critica | E10: Yessica | F10: 45672 | H10: Pendiente | I10: Video
A11: DEF-10 | B11: RF6 | C11: Los productos no se añaden a una lista de favoritos al dar click en el corazón | D11: Media | E11: Yessica | F11: 45672 | H11: Pendiente
A12: DEF-11 | B12: RF6 | C12: No se encuentra el módulo de lista de favoritos | D12: Alta | E12: Yessica | F12: 45672 | H12: Pendiente | I12: Imagen
A13: DEF-12 | B13: RF3 | C13: El menú lateral no funciona, y no podemos los demás módulos de la app | D13: Alta | E13: Yessica | F13: 45672 | H13: Pendiente | I13: Imagen
A14: DEF-13 | B14: RF8 | C14: No se pueden agregar direcciones | D14: Alta | E14: Yessica | F14: 45672 | H14: Pendiente | I14: Imagen
A15: DEF-14 | B15: RF8 | C15: No se encuentra la funcionalidad para agregar una dirección nueva | D15: Alta | E15: Yessica | F15: 45672 | H15: Pendiente
A16: DEF-15 | B16: RF8 | C16: Funcionalidad Faltante: No se encuentra disponible la opción ni el formulario para registrar un 'Nuevo Método de Pago'. | D16: Alta | E16: Yessica | F16: 45672 | H16: Pendiente
A17: DEF-16 | B17: RF1 | C17: Inconsistencia de UI vs HU: La Historia de Usuario (punto vii) exige un 'punto' dentro de la casilla de Términos, pero Figma despliega una 'palomita' (checkmark). | D17: Baja | E17: Yessica | F17: 45672 | H17: Pendiente
A18: DEF-17 | B18: RF1 | C18: Validación de los campos de nombre, contraseña, correo electronico, no se muestran | D18: Baja | E18: Yessica | F18: 45672 | H18: Pendiente
A19: DEF-18 | B19: RF1 | C19: No se encuenra la opción en el campo de visualizar contraseña | D19: Baja | E19: Yessica | F19: 45672 | H19: Pendiente
A20: DEF-19 | B20: RF1 | C20: No podemos ingresar al login con una cuenta registrada, porque al dar click en "inicio de sesión' no redirige a la pantalla de login | D20: Baja, Critica | E20: Yessica | F20: 45672 | H20: Pendiente
A21: DEF-20 | B21: RF5 | C21: Al seleccionar la catergoria de acciditos nos muestra una pantalla en negro | D21: Alta | E21: Yessica | F21: 45672 | H21: Pendiente | I21: Video

Sheet 6. Reporte Cierre QA
A1: INFORME DE CIERRE DE PRUEBAS
A2: Resumen Ejecutivo y Dictamen para Evaluación Técnica
A4: Proyecto: | B4: Módulo Uthis | D4: Versión: | E4: v1.0.0-PROD
A5: Responsable QA: | B5: Yessica Sánchez Beristain | D5: Dictamen Final: | E5: RECHAZADO (NO-GO) - RIESGO DE SEGURIDAD
A8: MÉTRICAS DE CASOS DE PRUEBA | E8: MÉTRICAS DE DEFECTOS
A9: Estado | B9: Cantidad | C9: % | E9: Criticidad | F9: Cantidad
A10: Exitoso | B10: =COUNTIF('4. Matriz Casos de Prueba'!G:G, A10) -> 11 | C10: =IF($B$14=0, 0, B10/$B$14) -> 0.22916667 | E10: Critica | F10: =COUNTIF('5. Incidencias y Bugs'!D:D, E10) -> 3
A11: Falló | B11: =COUNTIF('4. Matriz Casos de Prueba'!G:G, A11) -> 37 | C11: =IF($B$14=0, 0, B11/$B$14) -> 0.77083333 | E11: Alta | F11: =COUNTIF('5. Incidencias y Bugs'!D:D, E11) -> 8
A12: Diferido | B12: =COUNTIF('4. Matriz Casos de Prueba'!G:G, A12) -> 0 | C12: =IF($B$14=0, 0, B12/$B$14) -> 0 | E12: Media | F12: =COUNTIF('5. Incidencias y Bugs'!D:D, E12) -> 5
E13: Baja | F13: =COUNTIF('5. Incidencias y Bugs'!D:D, E13) -> 3
A14: Total | B14: =SUM(B10:B12) -> 48 | C14: =SUM(C10:C12) -> 1 | E14: Total | F14: =SUM(F10:F13) -> 19
